Workbook

Sheet 1_Raw_Data
A1: Row_ID | B1: Market | C1: Partner_Agency | D1: Campaign_Name | E1: Reported_Revenue | F1: Invoice_Amount | G1: Currency | H1: Month | I1: Status | J1: Notes
A2: 1 | B2: sweden | C2: WPP Media | D2: Q1 Brand Awareness | E2: 90278.31 | F2: 90278.31 | G2: EUR | H2: Feb-24 | I2: disputed | L2: =IF(A2="","Blank",IF(COUNTIF($A$2:A2,A2)=1,"Unique","Duplicate")) -> Unique | M2: =IF(L2="Unique",COUNTIF($L$2:L2,"Unique"),"") -> 1
A3: 2 | B3: Sweden | C3: IPG Mediabrands | D3: Q1 Brand Awareness | E3: 8426.68 | F3: 8426.68 | G3: gbp | H3: Jan-24 | I3: disputed | L3: =IF(A3="","Blank",IF(COUNTIF($A$2:A3,A3)=1,"Unique","Duplicate")) -> Unique | M3: =IF(L3="Unique",COUNTIF($L$2:L3,"Unique"),"") -> 2
A4: 3 | C4: Mindshare | D4: Premium Tier Push | E4: 30350.67 | F4: 29642.29 | G4: GBP | H4: 02/2024 | I4: Under review | J4: Check with agency | L4: =IF(A4="","Blank",IF(COUNTIF($A$2:A4,A4)=1,"Unique","Duplicate")) -> Unique | M4: =IF(L4="Unique",COUNTIF($L$2:L4,"Unique"),"") -> 3
A5: 4 | B5: Deutschland | C5: Publicis | D5: Q2 Retargeting Sweep | E5: 115079.5 | F5: 115079.5 | G5: EUR | H5: May-24 | I5: CONFIRMED | J5: Check with agency | L5: =IF(A5="","Blank",IF(COUNTIF($A$2:A5,A5)=1,"Unique","Duplicate")) -> Unique | M5: =IF(L5="Unique",COUNTIF($L$2:L5,"Unique"),"") -> 4
A6: 5 | B6: spain | C6: MediaCom | D6: Agency Co-op Feb | E6: 97819.75 | F6: 93665.93 | G6: GBP | H6: 01/2024 | I6: disputed | J6: Late invoice | L6: =IF(A6="","Blank",IF(COUNTIF($A$2:A6,A6)=1,"Unique","Duplicate")) -> Unique | M6: =IF(L6="Unique",COUNTIF($L$2:L6,"Unique"),"") -> 5
A7: 6 | B7: sweden | C7: MediaCom | D7: Data-Driven Creative | E7: 104096.29 | F7: 100902.62 | G7: GBP | H7: March 2024 | I7: pending | L7: =IF(A7="","Blank",IF(COUNTIF($A$2:A7,A7)=1,"Unique","Duplicate")) -> Unique | M7: =IF(L7="Unique",COUNTIF($L$2:L7,"Unique"),"") -> 6
A8: 7 | B8: DE | C8: WPP Media | D8: Premium Tier Push | E8: £36966.96 | F8: 34953.67 | G8: £ | H8: 04/2024 | I8: Pending | J8: Late invoice | L8: =IF(A8="","Blank",IF(COUNTIF($A$2:A8,A8)=1,"Unique","Duplicate")) -> Unique | M8: =IF(L8="Unique",COUNTIF($L$2:L8,"Unique"),"") -> 7
A9: 8 | B9: sweden | C9: WPP Media | D9: Always-On Display | E9: 78022.5 | F9: 73117.75 | G9: eur | H9: May-24 | I9: pending | J9: Original lost | L9: =IF(A9="","Blank",IF(COUNTIF($A$2:A9,A9)=1,"Unique","Duplicate")) -> Unique | M9: =IF(L9="Unique",COUNTIF($L$2:L9,"Unique"),"") -> 8
A10: 9 | B10: DE | C10: Havas Media | D10: Influencer Collab Feb | E10: 93356.06 | F10: 93356.06 | G10: GBP | H10: April 2024 | I10: Under review | J10: Late invoice | L10: =IF(A10="","Blank",IF(COUNTIF($A$2:A10,A10)=1,"Unique","Duplicate")) -> Unique | M10: =IF(L10="Unique",COUNTIF($L$2:L10,"Unique"),"") -> 9
A11: 10 | B11: U.K. | C11: Dentsu | D11: Data-Driven Creative | E11: 113434.62 | F11: 117067.64 | G11: eur | H11: May-24 | I11: Disputed | L11: =IF(A11="","Blank",IF(COUNTIF($A$2:A11,A11)=1,"Unique","Duplicate")) -> Unique | M11: =IF(L11="Unique",COUNTIF($L$2:L11,"Unique"),"") -> 10
A12: 11 | B12: Deutschland | C12: Publicis | D12: Q2 Retargeting Sweep | E12: 90673.73 | F12: 88161.25 | G12: GBP | H12: May-24 | I12: Under Review | L12: =IF(A12="","Blank",IF(COUNTIF($A$2:A12,A12)=1,"Unique","Duplicate")) -> Unique | M12: =IF(L12="Unique",COUNTIF($L$2:L12,"Unique"),"") -> 11
A13: 12 | B13: FRANCE | C13: Mindshare | D13: Winter Churn Prevention | E13: 15454.58 | G13: EUR | H13: February 2024 | I13: confirmed | J13: Amended | L13: =IF(A13="","Blank",IF(COUNTIF($A$2:A13,A13)=1,"Unique","Duplicate")) -> Unique | M13: =IF(L13="Unique",COUNTIF($L$2:L13,"Unique"),"") -> 12
A14: 13 | B14: SE | C14: WPP Media | D14: Premium Tier Push | E14: 48886.22 | F14: 51185.73 | G14: gbp | H14: Jan-24 | I14: CONFIRMED | J14: Original lost | L14: =IF(A14="","Blank",IF(COUNTIF($A$2:A14,A14)=1,"Unique","Duplicate")) -> Unique | M14: =IF(L14="Unique",COUNTIF($L$2:L14,"Unique"),"") -> 13
A15: 14 | B15: Deutschland | C15: Havas Media | D15: Subscriber Acquisition - Spring | E15: 38752.51 | F15: 38752.51 | G15: GBP | H15: 03/2024 | I15: disputed | L15: =IF(A15="","Blank",IF(COUNTIF($A$2:A15,A15)=1,"Unique","Duplicate")) -> Unique | M15: =IF(L15="Unique",COUNTIF($L$2:L15,"Unique"),"") -> 14
A16: 14 | B16: Deutschland | C16: Havas Media | D16: Subscriber Acquisition - Spring | E16: 38752.51 | F16: 38752.51 | G16: GBP | H16: 03/2024 | I16: disputed | L16: =IF(A16="","Blank",IF(COUNTIF($A$2:A16,A16)=1,"Unique","Duplicate")) -> Duplicate | M16: =IF(L16="Unique",COUNTIF($L$2:L16,"Unique"),"")
A17: 15 | B17: NL | C17: WPP Media | D17: Influencer Collab Feb | E17: 76909.52 | F17: 80411.7 | G17: EUR | H17: February 2024 | I17: Under Review | L17: =IF(A17="","Blank",IF(COUNTIF($A$2:A17,A17)=1,"Unique","Duplicate")) -> Unique | M17: =IF(L17="Unique",COUNTIF($L$2:L17,"Unique"),"") -> 15
A18: 16 | B18: The Netherlands | C18: Mindshare | D18: Data-Driven Creative | E18: 5065.77 | F18: 5065.77 | G18: GBP | H18: Feb-24 | I18: Under Review | J18: Late invoice | L18: =IF(A18="","Blank",IF(COUNTIF($A$2:A18,A18)=1,"Unique","Duplicate")) -> Unique | M18: =IF(L18="Unique",COUNTIF($L$2:L18,"Unique"),"") -> 16
A19: 17 | B19: DE | C19: GroupM | D19: Q2 Retargeting Sweep | E19: 105971.1 | F19: 107666.19 | G19: eur | H19: 01/2024 | I19: disputed | L19: =IF(A19="","Blank",IF(COUNTIF($A$2:A19,A19)=1,"Unique","Duplicate")) -> Unique | M19: =IF(L19="Unique",COUNTIF($L$2:L19,"Unique"),"") -> 17
A20: 18 | B20: FRANCE | C20: Hearts & Science | D20: EMEA Upfront Deal | E20: 23989.6 | F20: 23089.07 | G20: EUR | H20: 06/2024 | I20: Pending | J20: Late invoice | L20: =IF(A20="","Blank",IF(COUNTIF($A$2:A20,A20)=1,"Unique","Duplicate")) -> Unique | M20: =IF(L20="Unique",COUNTIF($L$2:L20,"Unique"),"") -> 18
A21: 19 | B21: Italy | C21: Havas Media | D21: Winter Churn Prevention | E21: 108455.62 | F21: 108455.62 | G21: EUR | H21: March 2024 | I21: CONFIRMED | J21: Check with agency | L21: =IF(A21="","Blank",IF(COUNTIF($A$2:A21,A21)=1,"Unique","Duplicate")) -> Unique | M21: =IF(L21="Unique",COUNTIF($L$2:L21,"Unique"),"") -> 19
A22: 20 | B22: UK | C22: MediaCom | D22: EMEA Upfront Deal | E22: 31463.19 | F22: 31463.19 | G22: EUR | H22: January 2024 | I22: Pending | L22: =IF(A22="","Blank",IF(COUNTIF($A$2:A22,A22)=1,"Unique","Duplicate")) -> Unique | M22: =IF(L22="Unique",COUNTIF($L$2:L22,"Unique"),"") -> 20
A23: 21 | B23: United Kingdom | C23: Havas Media | D23: Subscriber Acquisition - Spring | E23: 64127.95 | F23: 64127.95 | G23: eur | H23: Mar-24 | I23: disputed | L23: =IF(A23="","Blank",IF(COUNTIF($A$2:A23,A23)=1,"Unique","Duplicate")) -> Unique | M23: =IF(L23="Unique",COUNTIF($L$2:L23,"Unique"),"") -> 21
A24: 22 | B24: Sweden | C24: MediaCom | D24: Winter Churn Prevention | E24: 32944.68 | F24: 32944.68 | G24: GBP | H24: Mar-24 | I24: CONFIRMED | L24: =IF(A24="","Blank",IF(COUNTIF($A$2:A24,A24)=1,"Unique","Duplicate")) -> Unique | M24: =IF(L24="Unique",COUNTIF($L$2:L24,"Unique"),"") -> 22
A25: 23 | B25: IT | C25: Havas Media | D25: Premium Tier Push | E25: £52276.76 | F25: 52997.76 | G25: EUR | H25: January 2024 | I25: Under review | J25: Check with agency | L25: =IF(A25="","Blank",IF(COUNTIF($A$2:A25,A25)=1,"Unique","Duplicate")) -> Unique | M25: =IF(L25="Unique",COUNTIF($L$2:L25,"Unique"),"") -> 23
A26: 24 | B26: France | C26: Dentsu | D26: Q2 Retargeting Sweep | E26: 26874.02 | F26: 26874.02 | G26: GBP | H26: 02/2024 | I26: pending | J26: Re-sent | L26: =IF(A26="","Blank",IF(COUNTIF($A$2:A26,A26)=1,"Unique","Duplicate")) -> Unique | M26: =IF(L26="Unique",COUNTIF($L$2:L26,"Unique"),"") -> 24
A27: 25 | B27: DE | C27: WPP Media | D27: Winter Churn Prevention | E27: 97922.56 | F27: 99572.91 | G27: gbp | H27: Jan-24 | I27: CONFIRMED | L27: =IF(A27="","Blank",IF(COUNTIF($A$2:A27,A27)=1,"Unique","Duplicate")) -> Unique | M27: =IF(L27="Unique",COUNTIF($L$2:L27,"Unique"),"") -> 25
A28: 26 | B28: france | C28: IPG Mediabrands | D28: Winter Churn Prevention | E28: 60356.22 | F28: 64772.55 | G28: EUR | H28: May-24 | I28: Confirmed | J28: Amended | L28: =IF(A28="","Blank",IF(COUNTIF($A$2:A28,A28)=1,"Unique","Duplicate")) -> Unique | M28: =IF(L28="Unique",COUNTIF($L$2:L28,"Unique"),"") -> 26
A29: 27 | B29: Deutschland | C29: Hearts & Science | D29: Agency Co-op Feb | E29: 53645.86 | F29: 57920.34 | G29: gbp | H29: Jun-24 | I29: confirmed | L29: =IF(A29="","Blank",IF(COUNTIF($A$2:A29,A29)=1,"Unique","Duplicate")) -> Unique | M29: =IF(L29="Unique",COUNTIF($L$2:L29,"Unique"),"") -> 27
A30: 28 | B30: Spain | C30: Dentsu | D30: Q1 Brand Awareness | E30: 71605.73 | F30: 69626.43 | G30: GBP | H30: January 2024 | I30: Paid | J30: Re-sent | L30: =IF(A30="","Blank",IF(COUNTIF($A$2:A30,A30)=1,"Unique","Duplicate")) -> Unique | M30: =IF(L30="Unique",COUNTIF($L$2:L30,"Unique"),"") -> 28
A31: 29 | B31: NL | C31: Mindshare | D31: Content Promo Jan | E31: 11541.15 | F31: 11305.64 | G31: EUR | H31: 01/2024 | I31: Pending | J31: Amended | L31: =IF(A31="","Blank",IF(COUNTIF($A$2:A31,A31)=1,"Unique","Duplicate")) -> Unique | M31: =IF(L31="Unique",COUNTIF($L$2:L31,"Unique"),"") -> 29
A32: 30 | B32: France | C32: MediaCom | D32: Q2 Retargeting Sweep | E32: 71575.69 | F32: 71575.69 | G32: EUR | H32: May 2024 | I32: Paid | J32: Manual entry | L32: =IF(A32="","Blank",IF(COUNTIF($A$2:A32,A32)=1,"Unique","Duplicate")) -> Unique | M32: =IF(L32="Unique",COUNTIF($L$2:L32,"Unique"),"") -> 30
A33: 31 | B33: NL | C33: Havas Media | D33: Data-Driven Creative | E33: 34988.05 | F33: 32958.49 | G33: € | H33: May-24 | I33: confirmed | J33: Late invoice | L33: =IF(A33="","Blank",IF(COUNTIF($A$2:A33,A33)=1,"Unique","Duplicate")) -> Unique | M33: =IF(L33="Unique",COUNTIF($L$2:L33,"Unique"),"") -> 31
A34: 32 | B34: italia | C34: Havas Media | D34: Data-Driven Creative | E34: 91464.42 | F34: 91464.42 | G34: eur | H34: Feb-24 | I34: CONFIRMED | J34: Original lost | L34: =IF(A34="","Blank",IF(COUNTIF($A$2:A34,A34)=1,"Unique","Duplicate")) -> Unique | M34: =IF(L34="Unique",COUNTIF($L$2:L34,"Unique"),"") -> 32
A35: 33 | B35: Germany | C35: Mindshare | D35: Agency Co-op Feb | E35: 20232.51 | F35: 20232.51 | G35: EUR | H35: March 2024 | I35: Under Review | J35: Late invoice | L35: =IF(A35="","Blank",IF(COUNTIF($A$2:A35,A35)=1,"Unique","Duplicate")) -> Unique | M35: =IF(L35="Unique",COUNTIF($L$2:L35,"Unique"),"") -> 33
A36: 34 | B36: france | C36: Hearts & Science | D36: Influencer Collab Feb | E36: 67470.07 | G36: gbp | H36: Jan-24 | I36: disputed | J36: Late invoice | L36: =IF(A36="","Blank",IF(COUNTIF($A$2:A36,A36)=1,"Unique","Duplicate")) -> Unique | M36: =IF(L36="Unique",COUNTIF($L$2:L36,"Unique"),"") -> 34
A37: 35 | B37: France | C37: Publicis | D37: Agency Co-op Feb | E37: 18274.3 | F37: 18274.3 | G37: gbp | H37: February 2024 | I37: pending | J37: Late invoice | L37: =IF(A37="","Blank",IF(COUNTIF($A$2:A37,A37)=1,"Unique","Duplicate")) -> Unique | M37: =IF(L37="Unique",COUNTIF($L$2:L37,"Unique"),"") -> 35
A38: 36 | B38: SE | C38: Dentsu | D38: Performance Max Q1 | E38: 44431.23 | F38: 43529.45 | G38: gbp | H38: Jun-24 | I38: pending | L38: =IF(A38="","Blank",IF(COUNTIF($A$2:A38,A38)=1,"Unique","Duplicate")) -> Unique | M38: =IF(L38="Unique",COUNTIF($L$2:L38,"Unique"),"") -> 36
A39: 37 | B39: U.K. | C39: IPG Mediabrands | D39: Influencer Collab Feb | E39: 36818.23 | F39: 36818.23 | G39: EUR | H39: 03/2024 | I39: confirmed | J39: Re-sent | L39: =IF(A39="","Blank",IF(COUNTIF($A$2:A39,A39)=1,"Unique","Duplicate")) -> Unique | M39: =IF(L39="Unique",COUNTIF($L$2:L39,"Unique"),"") -> 37
A40: 38 | B40: The Netherlands | C40: IPG Mediabrands | D40: EMEA Upfront Deal | E40: 6112.02 | F40: 6112.02 | G40: EUR | H40: 06/2024 | I40: Confirmed | J40: Check with agency | L40: =IF(A40="","Blank",IF(COUNTIF($A$2:A40,A40)=1,"Unique","Duplicate")) -> Unique | M40: =IF(L40="Unique",COUNTIF($L$2:L40,"Unique"),"") -> 38
...

Sheet 2_Cleaned_Data
A1: Row_ID | B1: Market | C1: Partner_Agency | D1: Campaign_Name | E1: Reported_Revenue_GBP | F1: Invoice_Amount_GBP | G1: Currency_Original | H1: Month | I1: Status | J1: Notes | K1: Data_Issue_Flag | L1: FX_Rate
A2: =IFERROR(INDEX('1_Raw_Data'!$A:$A,MATCH(ROW()-1,'1_Raw_Data'!$M:$M,0)),"") -> 1 | B2: =IFERROR(VLOOKUP(LOWER(VLOOKUP(A2,'1_Raw_Data'!$A:$J,2,0)),LookupSheet!$A:$B,2,0),"MISSING") -> Sweden | C2: =VLOOKUP(A2,'1_Raw_Data'!$A:$J,3,0) -> WPP Media | D2: =VLOOKUP(A2,'1_Raw_Data'!$A:$J,4,0) -> Q1 Brand Awareness | E2: ='1_Raw_Data'!E2*L2 -> 77070.593 | F2: =IF('1_Raw_Data'!F2="","MISSING",'1_Raw_Data'!F2*L2) -> 77070.593 | G2: =UPPER(SUBSTITUTE(SUBSTITUTE(VLOOKUP(A2,'1_Raw_Data'!$A:$J,7,0),"€","EUR"),"£","GBP")) -> EUR | H2: =IFERROR(VLOOKUP(LOWER(VLOOKUP(A2,'1_Raw_Data'!$A:$J,8,0)),LookupSheet!$C:$D,2,0),IFERROR(VLOOKUP(LOWER(TEXT(VLOOKUP(A2,'1_Raw_Data'!$A:$J,8,0),"mmm-yy")),LookupSheet!$C:$D,2,0),VLOOKUP(A2,'1_Raw_Data'!$A:$J,8,0))) -> Feb-2024 | I2: =IFERROR(VLOOKUP(LOWER(VLOOKUP(A2,'1_Raw_Data'!$A:$J,9,0)),LookupSheet!$E:$F,2,0),VLOOKUP(A2,'1_Raw_Data'!$A:$J,9,0)) -> Disputed | J2: =IFERROR(IF(VLOOKUP(A2,'1_Raw_Data'!$A:$J,10,FALSE)="","",VLOOKUP(A2,'1_Raw_Data'!$A:$J,10,FALSE)),"") | K2: =IFERROR(IF(B2="UNKNOWN",$B$1&": Missing",IF(OR(F2="",F2="Invalid",F2="MISSING"),$F$1&": Missing",IF(OR(E2="",E2="Invalid",E2="MISSING"),$E$1&": Missing",IF(G2="",$G$1&": Missing",IF(H2="",$H$1&": Missing",IF(I2="",$I$1&": Missing","Clean")))))),"Clean") -> Clean | L2: =IF(G2="GBP",1,VLOOKUP(H2,FX_Rates!$A:$B,2,0)) -> 0.8537
A3: =IFERROR(INDEX('1_Raw_Data'!$A:$A,MATCH(ROW()-1,'1_Raw_Data'!$M:$M,0)),"") -> 2 | B3: =IFERROR(VLOOKUP(LOWER(VLOOKUP(A3,'1_Raw_Data'!$A:$J,2,0)),LookupSheet!$A:$B,2,0),"MISSING") -> Sweden | C3: =VLOOKUP(A3,'1_Raw_Data'!$A:$J,3,0) -> IPG Mediabrands | D3: =VLOOKUP(A3,'1_Raw_Data'!$A:$J,4,0) -> Q1 Brand Awareness | E3: ='1_Raw_Data'!E3*L3 -> 8426.68 | F3: =IF('1_Raw_Data'!F3="","MISSING",'1_Raw_Data'!F3*L3) -> 8426.68 | G3: =UPPER(SUBSTITUTE(SUBSTITUTE(VLOOKUP(A3,'1_Raw_Data'!$A:$J,7,0),"€","EUR"),"£","GBP")) -> GBP | H3: =IFERROR(VLOOKUP(LOWER(VLOOKUP(A3,'1_Raw_Data'!$A:$J,8,0)),LookupSheet!$C:$D,2,0),IFERROR(VLOOKUP(LOWER(TEXT(VLOOKUP(A3,'1_Raw_Data'!$A:$J,8,0),"mmm-yy")),LookupSheet!$C:$D,2,0),VLOOKUP(A3,'1_Raw_Data'!$A:$J,8,0))) -> Jan-2024 | I3: =IFERROR(VLOOKUP(LOWER(VLOOKUP(A3,'1_Raw_Data'!$A:$J,9,0)),LookupSheet!$E:$F,2,0),VLOOKUP(A3,'1_Raw_Data'!$A:$J,9,0)) -> Disputed | J3: =IFERROR(IF(VLOOKUP(A3,'1_Raw_Data'!$A:$J,10,FALSE)="","",VLOOKUP(A3,'1_Raw_Data'!$A:$J,10,FALSE)),"") | K3: =IFERROR(IF(B3="UNKNOWN",$B$1&": Missing",IF(OR(F3="",F3="Invalid",F3="MISSING"),$F$1&": Missing",IF(OR(E3="",E3="Invalid",E3="MISSING"),$E$1&": Missing",IF(G3="",$G$1&": Missing",IF(H3="",$H$1&": Missing",IF(I3="",$I$1&": Missing","Clean")))))),"Clean") -> Clean | L3: =IF(G3="GBP",1,VLOOKUP(H3,FX_Rates!$A:$B,2,0)) -> 1
A4: =IFERROR(INDEX('1_Raw_Data'!$A:$A,MATCH(ROW()-1,'1_Raw_Data'!$M:$M,0)),"") -> 3 | B4: =IFERROR(VLOOKUP(LOWER(VLOOKUP(A4,'1_Raw_Data'!$A:$J,2,0)),LookupSheet!$A:$B,2,0),"MISSING") -> MISSING | C4: =VLOOKUP(A4,'1_Raw_Data'!$A:$J,3,0) -> Mindshare | D4: =VLOOKUP(A4,'1_Raw_Data'!$A:$J,4,0) -> Premium Tier Push | E4: ='1_Raw_Data'!E4*L4 -> 30350.67 | F4: =IF('1_Raw_Data'!F4="","MISSING",'1_Raw_Data'!F4*L4) -> 29642.29 | G4: =UPPER(SUBSTITUTE(SUBSTITUTE(VLOOKUP(A4,'1_Raw_Data'!$A:$J,7,0),"€","EUR"),"£","GBP")) -> GBP | H4: =IFERROR(VLOOKUP(LOWER(VLOOKUP(A4,'1_Raw_Data'!$A:$J,8,0)),LookupSheet!$C:$D,2,0),IFERROR(VLOOKUP(LOWER(TEXT(VLOOKUP(A4,'1_Raw_Data'!$A:$J,8,0),"mmm-yy")),LookupSheet!$C:$D,2,0),VLOOKUP(A4,'1_Raw_Data'!$A:$J,8,0))) -> Feb-2024 | I4: =IFERROR(VLOOKUP(LOWER(VLOOKUP(A4,'1_Raw_Data'!$A:$J,9,0)),LookupSheet!$E:$F,2,0),VLOOKUP(A4,'1_Raw_Data'!$A:$J,9,0)) -> Under Review | J4: =IFERROR(IF(VLOOKUP(A4,'1_Raw_Data'!$A:$J,10,FALSE)="","",VLOOKUP(A4,'1_Raw_Data'!$A:$J,10,FALSE)),"") -> Check with agency | K4: =IFERROR(IF(B4="UNKNOWN",$B$1&": Missing",IF(OR(F4="",F4="Invalid",F4="MISSING"),$F$1&": Missing",IF(OR(E4="",E4="Invalid",E4="MISSING"),$E$1&": Missing",IF(G4="",$G$1&": Missing",IF(H4="",$H$1&": Missing",IF(I4="",$I$1&": Missing","Clean")))))),"Clean") -> Clean | L4: =IF(G4="GBP",1,VLOOKUP(H4,FX_Rates!$A:$B,2,0)) -> 1
A5: =IFERROR(INDEX('1_Raw_Data'!$A:$A,MATCH(ROW()-1,'1_Raw_Data'!$M:$M,0)),"") -> 4 | B5: =IFERROR(VLOOKUP(LOWER(VLOOKUP(A5,'1_Raw_Data'!$A:$J,2,0)),LookupSheet!$A:$B,2,0),"MISSING") -> Germany | C5: =VLOOKUP(A5,'1_Raw_Data'!$A:$J,3,0) -> Publicis | D5: =VLOOKUP(A5,'1_Raw_Data'!$A:$J,4,0) -> Q2 Retargeting Sweep | E5: ='1_Raw_Data'!E5*L5 -> 98197.337 | F5: =IF('1_Raw_Data'!F5="","MISSING",'1_Raw_Data'!F5*L5) -> 98197.337 | G5: =UPPER(SUBSTITUTE(SUBSTITUTE(VLOOKUP(A5,'1_Raw_Data'!$A:$J,7,0),"€","EUR"),"£","GBP")) -> EUR | H5: =IFERROR(VLOOKUP(LOWER(VLOOKUP(A5,'1_Raw_Data'!$A:$J,8,0)),LookupSheet!$C:$D,2,0),IFERROR(VLOOKUP(LOWER(TEXT(VLOOKUP(A5,'1_Raw_Data'!$A:$J,8,0),"mmm-yy")),LookupSheet!$C:$D,2,0),VLOOKUP(A5,'1_Raw_Data'!$A:$J,8,0))) -> May-2024 | I5: =IFERROR(VLOOKUP(LOWER(VLOOKUP(A5,'1_Raw_Data'!$A:$J,9,0)),LookupSheet!$E:$F,2,0),VLOOKUP(A5,'1_Raw_Data'!$A:$J,9,0)) -> Confirmed | J5: =IFERROR(IF(VLOOKUP(A5,'1_Raw_Data'!$A:$J,10,FALSE)="","",VLOOKUP(A5,'1_Raw_Data'!$A:$J,10,FALSE)),"") -> Check with agency | K5: =IFERROR(IF(B5="UNKNOWN",$B$1&": Missing",IF(OR(F5="",F5="Invalid",F5="MISSING"),$F$1&": Missing",IF(OR(E5="",E5="Invalid",E5="MISSING"),$E$1&": Missing",IF(G5="",$G$1&": Missing",IF(H5="",$H$1&": Missing",IF(I5="",$I$1&": Missing","Clean")))))),"Clean") -> Clean | L5: =IF(G5="GBP",1,VLOOKUP(H5,FX_Rates!$A:$B,2,0)) -> 0.8533
A6: =IFERROR(INDEX('1_Raw_Data'!$A:$A,MATCH(ROW()-1,'1_Raw_Data'!$M:$M,0)),"") -> 5 | B6: =IFERROR(VLOOKUP(LOWER(VLOOKUP(A6,'1_Raw_Data'!$A:$J,2,0)),LookupSheet!$A:$B,2,0),"MISSING") -> Spain | C6: =VLOOKUP(A6,'1_Raw_Data'!$A:$J,3,0) -> MediaCom | D6: =VLOOKUP(A6,'1_Raw_Data'!$A:$J,4,0) -> Agency Co-op Feb | E6: ='1_Raw_Data'!E6*L6 -> 97819.75 | F6: =IF('1_Raw_Data'!F6="","MISSING",'1_Raw_Data'!F6*L6) -> 93665.93 | G6: =UPPER(SUBSTITUTE(SUBSTITUTE(VLOOKUP(A6,'1_Raw_Data'!$A:$J,7,0),"€","EUR"),"£","GBP")) -> GBP | H6: =IFERROR(VLOOKUP(LOWER(VLOOKUP(A6,'1_Raw_Data'!$A:$J,8,0)),LookupSheet!$C:$D,2,0),IFERROR(VLOOKUP(LOWER(TEXT(VLOOKUP(A6,'1_Raw_Data'!$A:$J,8,0),"mmm-yy")),LookupSheet!$C:$D,2,0),VLOOKUP(A6,'1_Raw_Data'!$A:$J,8,0))) -> Jan-2024 | I6: =IFERROR(VLOOKUP(LOWER(VLOOKUP(A6,'1_Raw_Data'!$A:$J,9,0)),LookupSheet!$E:$F,2,0),VLOOKUP(A6,'1_Raw_Data'!$A:$J,9,0)) -> Disputed | J6: =IFERROR(IF(VLOOKUP(A6,'1_Raw_Data'!$A:$J,10,FALSE)="","",VLOOKUP(A6,'1_Raw_Data'!$A:$J,10,FALSE)),"") -> Late invoice | K6: =IFERROR(IF(B6="UNKNOWN",$B$1&": Missing",IF(OR(F6="",F6="Invalid",F6="MISSING"),$F$1&": Missing",IF(OR(E6="",E6="Invalid",E6="MISSING"),$E$1&": Missing",IF(G6="",$G$1&": Missing",IF(H6="",$H$1&": Missing",IF(I6="",$I$1&": Missing","Clean")))))),"Clean") -> Clean | L6: =IF(G6="GBP",1,VLOOKUP(H6,FX_Rates!$A:$B,2,0)) -> 1
A7: =IFERROR(INDEX('1_Raw_Data'!$A:$A,MATCH(ROW()-1,'1_Raw_Data'!$M:$M,0)),"") -> 6 | B7: =IFERROR(VLOOKUP(LOWER(VLOOKUP(A7,'1_Raw_Data'!$A:$J,2,0)),LookupSheet!$A:$B,2,0),"MISSING") -> Sweden | C7: =VLOOKUP(A7,'1_Raw_Data'!$A:$J,3,0) -> MediaCom | D7: =VLOOKUP(A7,'1_Raw_Data'!$A:$J,4,0) -> Data-Driven Creative | E7: ='1_Raw_Data'!E7*L7 -> 104096.29 | F7: =IF('1_Raw_Data'!F7="","MISSING",'1_Raw_Data'!F7*L7) -> 100902.62 | G7: =UPPER(SUBSTITUTE(SUBSTITUTE(VLOOKUP(A7,'1_Raw_Data'!$A:$J,7,0),"€","EUR"),"£","GBP")) -> GBP | H7: =IFERROR(VLOOKUP(LOWER(VLOOKUP(A7,'1_Raw_Data'!$A:$J,8,0)),LookupSheet!$C:$D,2,0),IFERROR(VLOOKUP(LOWER(TEXT(VLOOKUP(A7,'1_Raw_Data'!$A:$J,8,0),"mmm-yy")),LookupSheet!$C:$D,2,0),VLOOKUP(A7,'1_Raw_Data'!$A:$J,8,0))) -> Mar-2024 | I7: =IFERROR(VLOOKUP(LOWER(VLOOKUP(A7,'1_Raw_Data'!$A:$J,9,0)),LookupSheet!$E:$F,2,0),VLOOKUP(A7,'1_Raw_Data'!$A:$J,9,0)) -> Pending | J7: =IFERROR(IF(VLOOKUP(A7,'1_Raw_Data'!$A:$J,10,FALSE)="","",VLOOKUP(A7,'1_Raw_Data'!$A:$J,10,FALSE)),"") | K7: =IFERROR(IF(B7="UNKNOWN",$B$1&": Missing",IF(OR(F7="",F7="Invalid",F7="MISSING"),$F$1&": Missing",IF(OR(E7="",E7="Invalid",E7="MISSING"),$E$1&": Missing",IF(G7="",$G$1&": Missing",IF(H7="",$H$1&": Missing",IF(I7="",$I$1&": Missing","Clean")))))),"Clean") -> Clean | L7: =IF(G7="GBP",1,VLOOKUP(H7,FX_Rates!$A:$B,2,0)) -> 1
A8: =IFERROR(INDEX('1_Raw_Data'!$A:$A,MATCH(ROW()-1,'1_Raw_Data'!$M:$M,0)),"") -> 7 | B8: =IFERROR(VLOOKUP(LOWER(VLOOKUP(A8,'1_Raw_Data'!$A:$J,2,0)),LookupSheet!$A:$B,2,0),"MISSING") -> Germany | C8: =VLOOKUP(A8,'1_Raw_Data'!$A:$J,3,0) -> WPP Media | D8: =VLOOKUP(A8,'1_Raw_Data'!$A:$J,4,0) -> Premium Tier Push | E8: ='1_Raw_Data'!E8*L8 -> 36966.96 | F8: =IF('1_Raw_Data'!F8="","MISSING",'1_Raw_Data'!F8*L8) -> 34953.67 | G8: =UPPER(SUBSTITUTE(SUBSTITUTE(VLOOKUP(A8,'1_Raw_Data'!$A:$J,7,0),"€","EUR"),"£","GBP")) -> GBP | H8: =IFERROR(VLOOKUP(LOWER(VLOOKUP(A8,'1_Raw_Data'!$A:$J,8,0)),LookupSheet!$C:$D,2,0),IFERROR(VLOOKUP(LOWER(TEXT(VLOOKUP(A8,'1_Raw_Data'!$A:$J,8,0),"mmm-yy")),LookupSheet!$C:$D,2,0),VLOOKUP(A8,'1_Raw_Data'!$A:$J,8,0))) -> Apr-2024 | I8: =IFERROR(VLOOKUP(LOWER(VLOOKUP(A8,'1_Raw_Data'!$A:$J,9,0)),LookupSheet!$E:$F,2,0),VLOOKUP(A8,'1_Raw_Data'!$A:$J,9,0)) -> Pending | J8: =IFERROR(IF(VLOOKUP(A8,'1_Raw_Data'!$A:$J,10,FALSE)="","",VLOOKUP(A8,'1_Raw_Data'!$A:$J,10,FALSE)),"") -> Late invoice | K8: =IFERROR(IF(B8="UNKNOWN",$B$1&": Missing",IF(OR(F8="",F8="Invalid",F8="MISSING"),$F$1&": Missing",IF(OR(E8="",E8="Invalid",E8="MISSING"),$E$1&": Missing",IF(G8="",$G$1&": Missing",IF(H8="",$H$1&": Missing",IF(I8="",$I$1&": Missing","Clean")))))),"Clean") -> Clean | L8: =IF(G8="GBP",1,VLOOKUP(H8,FX_Rates!$A:$B,2,0)) -> 1
A9: =IFERROR(INDEX('1_Raw_Data'!$A:$A,MATCH(ROW()-1,'1_Raw_Data'!$M:$M,0)),"") -> 8 | B9: =IFERROR(VLOOKUP(LOWER(VLOOKUP(A9,'1_Raw_Data'!$A:$J,2,0)),LookupSheet!$A:$B,2,0),"MISSING") -> Sweden | C9: =VLOOKUP(A9,'1_Raw_Data'!$A:$J,3,0) -> WPP Media | D9: =VLOOKUP(A9,'1_Raw_Data'!$A:$J,4,0) -> Always-On Display | E9: ='1_Raw_Data'!E9*L9 -> 66576.599 | F9: =IF('1_Raw_Data'!F9="","MISSING",'1_Raw_Data'!F9*L9) -> 62391.376 | G9: =UPPER(SUBSTITUTE(SUBSTITUTE(VLOOKUP(A9,'1_Raw_Data'!$A:$J,7,0),"€","EUR"),"£","GBP")) -> EUR | H9: =IFERROR(VLOOKUP(LOWER(VLOOKUP(A9,'1_Raw_Data'!$A:$J,8,0)),LookupSheet!$C:$D,2,0),IFERROR(VLOOKUP(LOWER(TEXT(VLOOKUP(A9,'1_Raw_Data'!$A:$J,8,0),"mmm-yy")),LookupSheet!$C:$D,2,0),VLOOKUP(A9,'1_Raw_Data'!$A:$J,8,0))) -> May-2024 | I9: =IFERROR(VLOOKUP(LOWER(VLOOKUP(A9,'1_Raw_Data'!$A:$J,9,0)),LookupSheet!$E:$F,2,0),VLOOKUP(A9,'1_Raw_Data'!$A:$J,9,0)) -> Pending | J9: =IFERROR(IF(VLOOKUP(A9,'1_Raw_Data'!$A:$J,10,FALSE)="","",VLOOKUP(A9,'1_Raw_Data'!$A:$J,10,FALSE)),"") -> Original lost | K9: =IFERROR(IF(B9="UNKNOWN",$B$1&": Missing",IF(OR(F9="",F9="Invalid",F9="MISSING"),$F$1&": Missing",IF(OR(E9="",E9="Invalid",E9="MISSING"),$E$1&": Missing",IF(G9="",$G$1&": Missing",IF(H9="",$H$1&": Missing",IF(I9="",$I$1&": Missing","Clean")))))),"Clean") -> Clean | L9: =IF(G9="GBP",1,VLOOKUP(H9,FX_Rates!$A:$B,2,0)) -> 0.8533
A10: =IFERROR(INDEX('1_Raw_Data'!$A:$A,MATCH(ROW()-1,'1_Raw_Data'!$M:$M,0)),"") -> 9 | B10: =IFERROR(VLOOKUP(LOWER(VLOOKUP(A10,'1_Raw_Data'!$A:$J,2,0)),LookupSheet!$A:$B,2,0),"MISSING") -> Germany | C10: =VLOOKUP(A10,'1_Raw_Data'!$A:$J,3,0) -> Havas Media | D10: =VLOOKUP(A10,'1_Raw_Data'!$A:$J,4,0) -> Influencer Collab Feb | E10: ='1_Raw_Data'!E10*L10 -> 93356.06 | F10: =IF('1_Raw_Data'!F10="","MISSING",'1_Raw_Data'!F10*L10) -> 93356.06 | G10: =UPPER(SUBSTITUTE(SUBSTITUTE(VLOOKUP(A10,'1_Raw_Data'!$A:$J,7,0),"€","EUR"),"£","GBP")) -> GBP | H10: =IFERROR(VLOOKUP(LOWER(VLOOKUP(A10,'1_Raw_Data'!$A:$J,8,0)),LookupSheet!$C:$D,2,0),IFERROR(VLOOKUP(LOWER(TEXT(VLOOKUP(A10,'1_Raw_Data'!$A:$J,8,0),"mmm-yy")),LookupSheet!$C:$D,2,0),VLOOKUP(A10,'1_Raw_Data'!$A:$J,8,0))) -> Apr-2024 | I10: =IFERROR(VLOOKUP(LOWER(VLOOKUP(A10,'1_Raw_Data'!$A:$J,9,0)),LookupSheet!$E:$F,2,0),VLOOKUP(A10,'1_Raw_Data'!$A:$J,9,0)) -> Under Review | J10: =IFERROR(IF(VLOOKUP(A10,'1_Raw_Data'!$A:$J,10,FALSE)="","",VLOOKUP(A10,'1_Raw_Data'!$A:$J,10,FALSE)),"") -> Late invoice | K10: =IFERROR(IF(B10="UNKNOWN",$B$1&": Missing",IF(OR(F10="",F10="Invalid",F10="MISSING"),$F$1&": Missing",IF(OR(E10="",E10="Invalid",E10="MISSING"),$E$1&": Missing",IF(G10="",$G$1&": Missing",IF(H10="",$H$1&": Missing",IF(I10="",$I$1&": Missing","Clean")))))),"Clean") -> Clean | L10: =IF(G10="GBP",1,VLOOKUP(H10,FX_Rates!$A:$B,2,0)) -> 1
A11: =IFERROR(INDEX('1_Raw_Data'!$A:$A,MATCH(ROW()-1,'1_Raw_Data'!$M:$M,0)),"") -> 10 | B11: =IFERROR(VLOOKUP(LOWER(VLOOKUP(A11,'1_Raw_Data'!$A:$J,2,0)),LookupSheet!$A:$B,2,0),"MISSING") -> UK | C11: =VLOOKUP(A11,'1_Raw_Data'!$A:$J,3,0) -> Dentsu | D11: =VLOOKUP(A11,'1_Raw_Data'!$A:$J,4,0) -> Data-Driven Creative | E11: ='1_Raw_Data'!E11*L11 -> 96793.761 | F11: =IF('1_Raw_Data'!F11="","MISSING",'1_Raw_Data'!F11*L11) -> 99893.817 | G11: =UPPER(SUBSTITUTE(SUBSTITUTE(VLOOKUP(A11,'1_Raw_Data'!$A:$J,7,0),"€","EUR"),"£","GBP")) -> EUR | H11: =IFERROR(VLOOKUP(LOWER(VLOOKUP(A11,'1_Raw_Data'!$A:$J,8,0)),LookupSheet!$C:$D,2,0),IFERROR(VLOOKUP(LOWER(TEXT(VLOOKUP(A11,'1_Raw_Data'!$A:$J,8,0),"mmm-yy")),LookupSheet!$C:$D,2,0),VLOOKUP(A11,'1_Raw_Data'!$A:$J,8,0))) -> May-2024 | I11: =IFERROR(VLOOKUP(LOWER(VLOOKUP(A11,'1_Raw_Data'!$A:$J,9,0)),LookupSheet!$E:$F,2,0),VLOOKUP(A11,'1_Raw_Data'!$A:$J,9,0)) -> Disputed | J11: =IFERROR(IF(VLOOKUP(A11,'1_Raw_Data'!$A:$J,10,FALSE)="","",VLOOKUP(A11,'1_Raw_Data'!$A:$J,10,FALSE)),"") | K11: =IFERROR(IF(B11="UNKNOWN",$B$1&": Missing",IF(OR(F11="",F11="Invalid",F11="MISSING"),$F$1&": Missing",IF(OR(E11="",E11="Invalid",E11="MISSING"),$E$1&": Missing",IF(G11="",$G$1&": Missing",IF(H11="",$H$1&": Missing",IF(I11="",$I$1&": Missing","Clean")))))),"Clean") -> Clean | L11: =IF(G11="GBP",1,VLOOKUP(H11,FX_Rates!$A:$B,2,0)) -> 0.8533
A12: =IFERROR(INDEX('1_Raw_Data'!$A:$A,MATCH(ROW()-1,'1_Raw_Data'!$M:$M,0)),"") -> 11 | B12: =IFERROR(VLOOKUP(LOWER(VLOOKUP(A12,'1_Raw_Data'!$A:$J,2,0)),LookupSheet!$A:$B,2,0),"MISSING") -> Germany | C12: =VLOOKUP(A12,'1_Raw_Data'!$A:$J,3,0) -> Publicis | D12: =VLOOKUP(A12,'1_Raw_Data'!$A:$J,4,0) -> Q2 Retargeting Sweep | E12: ='1_Raw_Data'!E12*L12 -> 90673.73 | F12: =IF('1_Raw_Data'!F12="","MISSING",'1_Raw_Data'!F12*L12) -> 88161.25 | G12: =UPPER(SUBSTITUTE(SUBSTITUTE(VLOOKUP(A12,'1_Raw_Data'!$A:$J,7,0),"€","EUR"),"£","GBP")) -> GBP | H12: =IFERROR(VLOOKUP(LOWER(VLOOKUP(A12,'1_Raw_Data'!$A:$J,8,0)),LookupSheet!$C:$D,2,0),IFERROR(VLOOKUP(LOWER(TEXT(VLOOKUP(A12,'1_Raw_Data'!$A:$J,8,0),"mmm-yy")),LookupSheet!$C:$D,2,0),VLOOKUP(A12,'1_Raw_Data'!$A:$J,8,0))) -> May-2024 | I12: =IFERROR(VLOOKUP(LOWER(VLOOKUP(A12,'1_Raw_Data'!$A:$J,9,0)),LookupSheet!$E:$F,2,0),VLOOKUP(A12,'1_Raw_Data'!$A:$J,9,0)) -> Under Review | J12: =IFERROR(IF(VLOOKUP(A12,'1_Raw_Data'!$A:$J,10,FALSE)="","",VLOOKUP(A12,'1_Raw_Data'!$A:$J,10,FALSE)),"") | K12: =IFERROR(IF(B12="UNKNOWN",$B$1&": Missing",IF(OR(F12="",F12="Invalid",F12="MISSING"),$F$1&": Missing",IF(OR(E12="",E12="Invalid",E12="MISSING"),$E$1&": Missing",IF(G12="",$G$1&": Missing",IF(H12="",$H$1&": Missing",IF(I12="",$I$1&": Missing","Clean")))))),"Clean") -> Clean | L12: =IF(G12="GBP",1,VLOOKUP(H12,FX_Rates!$A:$B,2,0)) -> 1
A13: =IFERROR(INDEX('1_Raw_Data'!$A:$A,MATCH(ROW()-1,'1_Raw_Data'!$M:$M,0)),"") -> 12 | B13: =IFERROR(VLOOKUP(LOWER(VLOOKUP(A13,'1_Raw_Data'!$A:$J,2,0)),LookupSheet!$A:$B,2,0),"MISSING") -> France | C13: =VLOOKUP(A13,'1_Raw_Data'!$A:$J,3,0) -> Mindshare | D13: =VLOOKUP(A13,'1_Raw_Data'!$A:$J,4,0) -> Winter Churn Prevention | E13: ='1_Raw_Data'!E13*L13 -> 13193.575 | F13: =IF('1_Raw_Data'!F13="","MISSING",'1_Raw_Data'!F13*L13) -> MISSING | G13: =UPPER(SUBSTITUTE(SUBSTITUTE(VLOOKUP(A13,'1_Raw_Data'!$A:$J,7,0),"€","EUR"),"£","GBP")) -> EUR | H13: =IFERROR(VLOOKUP(LOWER(VLOOKUP(A13,'1_Raw_Data'!$A:$J,8,0)),LookupSheet!$C:$D,2,0),IFERROR(VLOOKUP(LOWER(TEXT(VLOOKUP(A13,'1_Raw_Data'!$A:$J,8,0),"mmm-yy")),LookupSheet!$C:$D,2,0),VLOOKUP(A13,'1_Raw_Data'!$A:$J,8,0))) -> Feb-2024 | I13: =IFERROR(VLOOKUP(LOWER(VLOOKUP(A13,'1_Raw_Data'!$A:$J,9,0)),LookupSheet!$E:$F,2,0),VLOOKUP(A13,'1_Raw_Data'!$A:$J,9,0)) -> Confirmed | J13: =IFERROR(IF(VLOOKUP(A13,'1_Raw_Data'!$A:$J,10,FALSE)="","",VLOOKUP(A13,'1_Raw_Data'!$A:$J,10,FALSE)),"") -> Amended | K13: =IFERROR(IF(B13="UNKNOWN",$B$1&": Missing",IF(OR(F13="",F13="Invalid",F13="MISSING"),$F$1&": Missing",IF(OR(E13="",E13="Invalid",E13="MISSING"),$E$1&": Missing",IF(G13="",$G$1&": Missing",IF(H13="",$H$1&": Missing",IF(I13="",$I$1&": Missing","Clean")))))),"Clean") -> Invoice_Amount_GBP: Missing | L13: =IF(G13="GBP",1,VLOOKUP(H13,FX_Rates!$A:$B,2,0)) -> 0.8537
... A101: =IFERROR(INDEX('1_Raw_Data'!$A:$A,MATCH(ROW()-1,'1_Raw_Data'!$M:$M,0)),"") -> 100 | B101: =IFERROR(VLOOKUP(LOWER(VLOOKUP(A101,'1_Raw_Data'!$A:$J,2,0)),LookupSheet!$A:$B,2,0),"MISSING") -> Spain | C101: =VLOOKUP(A101,'1_Raw_Data'!$A:$J,3,0) -> Mindshare | D101: =VLOOKUP(A101,'1_Raw_Data'!$A:$J,4,0) -> Agency Co-op Feb | E101: ='1_Raw_Data'!E101*L101 -> 72687.255 | F101: =IF('1_Raw_Data'!F101="","MISSING",'1_Raw_Data'!F101*L101) -> 72687.255 | G101: =UPPER(SUBSTITUTE(SUBSTITUTE(VLOOKUP(A101,'1_Raw_Data'!$A:$J,7,0),"€","EUR"),"£","GBP")) -> EUR | H101: =IFERROR(VLOOKUP(LOWER(VLOOKUP(A101,'1_Raw_Data'!$A:$J,8,0)),LookupSheet!$C:$D,2,0),IFERROR(VLOOKUP(LOWER(TEXT(VLOOKUP(A101,'1_Raw_Data'!$A:$J,8,0),"mmm-yy")),LookupSheet!$C:$D,2,0),VLOOKUP(A101,'1_Raw_Data'!$A:$J,8,0))) -> Jun-2024 | I101: =IFERROR(VLOOKUP(LOWER(VLOOKUP(A101,'1_Raw_Data'!$A:$J,9,0)),LookupSheet!$E:$F,2,0),VLOOKUP(A101,'1_Raw_Data'!$A:$J,9,0)) -> Confirmed | J101: =IFERROR(IF(VLOOKUP(A101,'1_Raw_Data'!$A:$J,10,FALSE)="","",VLOOKUP(A101,'1_Raw_Data'!$A:$J,10,FALSE)),"") -> Re-sent | K101: =IFERROR(IF(B101="UNKNOWN",$B$1&": Missing",IF(OR(F101="",F101="Invalid",F101="MISSING"),$F$1&": Missing",IF(OR(E101="",E101="Invalid",E101="MISSING"),$E$1&": Missing",IF(G101="",$G$1&": Missing",IF(H101="",$H$1&": Missing",IF(I101="",$I$1&": Missing","Clean")))))),"Clean") -> Clean | L101: =IF(G101="GBP",1,VLOOKUP(H101,FX_Rates!$A:$B,2,0)) -> 0.844

Sheet 3_Reconciliation
A1: Row_ID | B1: Market | C1: Partner_Agency | D1: Month | E1: Reported_Revenue_GBP | F1: Invoice_Amount_GBP | G1: Variance_GBP | H1: Variance_Pct | I1: Recon_Status
A2: 1 | B2: Sweden | C2: WPP Media | D2: Feb-2024 | E2: 77639.35 | F2: 77639.35 | G2: =F2-E2 -> 0 | H2: =IFERROR((F2-E2)/E2,0) -> 0 | I2: =IF(ABS(H2)<=0.01,"Match",IF(ABS(H2)<=0.05,"Review","Escalate")) -> Match
A3: 2 | B3: Sweden | C3: IPG Mediabrands | D3: Jan-2024 | E3: 8426.68 | F3: 8426.68 | G3: =F3-E3 -> 0 | H3: =IFERROR((F3-E3)/E3,0) -> 0 | I3: =IF(ABS(H3)<=0.01,"Match",IF(ABS(H3)<=0.05,"Review","Escalate")) -> Match
A4: 3 | B4: UNKNOWN | C4: Mindshare | D4: Feb-2024 | E4: 30350.67 | F4: 29642.29 | G4: =F4-E4 -> -708.38 | H4: =IFERROR((F4-E4)/E4,0) -> -0.023339847 | I4: =IF(ABS(H4)<=0.01,"Match",IF(ABS(H4)<=0.05,"Review","Escalate")) -> Review
A5: 4 | B5: Germany | C5: Publicis | D5: May-2024 | E5: 98968.37 | F5: 98968.37 | G5: =F5-E5 -> 0 | H5: =IFERROR((F5-E5)/E5,0) -> 0 | I5: =IF(ABS(H5)<=0.01,"Match",IF(ABS(H5)<=0.05,"Review","Escalate")) -> Match
A6: 5 | B6: Spain | C6: MediaCom | D6: Jan-2024 | E6: 97819.75 | F6: 93665.93 | G6: =F6-E6 -> -4153.82 | H6: =IFERROR((F6-E6)/E6,0) -> -0.042464022 | I6: =IF(ABS(H6)<=0.01,"Match",IF(ABS(H6)<=0.05,"Review","Escalate")) -> Review
A7: 6 | B7: Sweden | C7: MediaCom | D7: Mar-2024 | E7: 104096.29 | F7: 100902.62 | G7: =F7-E7 -> -3193.67 | H7: =IFERROR((F7-E7)/E7,0) -> -0.03067996 | I7: =IF(ABS(H7)<=0.01,"Match",IF(ABS(H7)<=0.05,"Review","Escalate")) -> Review
A8: 7 | B8: Germany | C8: WPP Media | D8: Apr-2024 | E8: 36966.96 | F8: 34953.67 | G8: =F8-E8 -> -2013.29 | H8: =IFERROR((F8-E8)/E8,0) -> -0.054461876 | I8: =IF(ABS(H8)<=0.01,"Match",IF(ABS(H8)<=0.05,"Review","Escalate")) -> Escalate
A9: 8 | B9: Sweden | C9: WPP Media | D9: May-2024 | E9: 67099.35 | F9: 62881.26 | G9: =F9-E9 -> -4218.09 | H9: =IFERROR((F9-E9)/E9,0) -> -0.062863351 | I9: =IF(ABS(H9)<=0.01,"Match",IF(ABS(H9)<=0.05,"Review","Escalate")) -> Escalate
A10: 9 | B10: Germany | C10: Havas Media | D10: Apr-2024 | E10: 93356.06 | F10: 93356.06 | G10: =F10-E10 -> 0 | H10: =IFERROR((F10-E10)/E10,0) -> 0 | I10: =IF(ABS(H10)<=0.01,"Match",IF(ABS(H10)<=0.05,"Review","Escalate")) -> Match
A11: 10 | B11: UK | C11: Dentsu | D11: May-2024 | E11: 97553.77 | F11: 100678.17 | G11: =F11-E11 -> 3124.4 | H11: =IFERROR((F11-E11)/E11,0) -> 0.032027465 | I11: =IF(ABS(H11)<=0.01,"Match",IF(ABS(H11)<=0.05,"Review","Escalate")) -> Review
A12: 11 | B12: Germany | C12: Publicis | D12: May-2024 | E12: 90673.73 | F12: 88161.25 | G12: =F12-E12 -> -2512.48 | H12: =IFERROR((F12-E12)/E12,0) -> -0.027709018 | I12: =IF(ABS(H12)<=0.01,"Match",IF(ABS(H12)<=0.05,"Review","Escalate")) -> Review
A13: 12 | B13: France | C13: Mindshare | D13: Feb-2024 | E13: 13193.57 | F13: Missing | G13: N/A | H13: N/A | I13: Missing Invoice
A14: 13 | B14: Sweden | C14: WPP Media | D14: Jan-2024 | E14: 48886.22 | F14: 51185.73 | G14: =F14-E14 -> 2299.51 | H14: =IFERROR((F14-E14)/E14,0) -> 0.047038 | I14: =IF(ABS(H14)<=0.01,"Match",IF(ABS(H14)<=0.05,"Review","Escalate")) -> Review
A15: 14 | B15: Germany | C15: Havas Media | D15: Mar-2024 | E15: 38752.51 | F15: 38752.51 | G15: =F15-E15 -> 0 | H15: =IFERROR((F15-E15)/E15,0) -> 0 | I15: =IF(ABS(H15)<=0.01,"Match",IF(ABS(H15)<=0.05,"Review","Escalate")) -> Match
A16: 15 | B16: Netherlands | C16: WPP Media | D16: Feb-2024 | E16: 66142.19 | F16: 69154.06 | G16: =F16-E16 -> 3011.87 | H16: =IFERROR((F16-E16)/E16,0) -> 0.045536291 | I16: =IF(ABS(H16)<=0.01,"Match",IF(ABS(H16)<=0.05,"Review","Escalate")) -> Review
A17: 16 | B17: Netherlands | C17: Mindshare | D17: Feb-2024 | E17: 5065.77 | F17: 5065.77 | G17: =F17-E17 -> 0 | H17: =IFERROR((F17-E17)/E17,0) -> 0 | I17: =IF(ABS(H17)<=0.01,"Match",IF(ABS(H17)<=0.05,"Review","Escalate")) -> Match
A18: 17 | B18: Germany | C18: GroupM | D18: Jan-2024 | E18: 91135.15 | F18: 92592.92 | G18: =F18-E18 -> 1457.77 | H18: =IFERROR((F18-E18)/E18,0) -> 0.015995694 | I18: =IF(ABS(H18)<=0.01,"Match",IF(ABS(H18)<=0.05,"Review","Escalate")) -> Review
A19: 18 | B19: France | C19: Hearts & Science | D19: Jun-2024 | E19: 20631.06 | F19: 19856.6 | G19: =F19-E19 -> -774.46 | H19: =IFERROR((F19-E19)/E19,0) -> -0.037538546 | I19: =IF(ABS(H19)<=0.01,"Match",IF(ABS(H19)<=0.05,"Review","Escalate")) -> Review
A20: 19 | B20: Italy | C20: Havas Media | D20: Mar-2024 | E20: 93271.83 | F20: 93271.83 | G20: =F20-E20 -> 0 | H20: =IFERROR((F20-E20)/E20,0) -> 0 | I20: =IF(ABS(H20)<=0.01,"Match",IF(ABS(H20)<=0.05,"Review","Escalate")) -> Match
A21: 20 | B21: UK | C21: MediaCom | D21: Jan-2024 | E21: 27058.34 | F21: 27058.34 | G21: =F21-E21 -> 0 | H21: =IFERROR((F21-E21)/E21,0) -> 0 | I21: =IF(ABS(H21)<=0.01,"Match",IF(ABS(H21)<=0.05,"Review","Escalate")) -> Match
A22: 21 | B22: UK | C22: Havas Media | D22: Mar-2024 | E22: 55150.04 | F22: 55150.04 | G22: =F22-E22 -> 0 | H22: =IFERROR((F22-E22)/E22,0) -> 0 | I22: =IF(ABS(H22)<=0.01,"Match",IF(ABS(H22)<=0.05,"Review","Escalate")) -> Match
A23: 22 | B23: Sweden | C23: MediaCom | D23: Mar-2024 | E23: 32944.68 | F23: 32944.68 | G23: =F23-E23 -> 0 | H23: =IFERROR((F23-E23)/E23,0) -> 0 | I23: =IF(ABS(H23)<=0.01,"Match",IF(ABS(H23)<=0.05,"Review","Escalate")) -> Match
A24: 23 | B24: Italy | C24: Havas Media | D24: Jan-2024 | E24: 44958.01 | F24: 45578.07 | G24: =F24-E24 -> 620.06 | H24: =IFERROR((F24-E24)/E24,0) -> 0.013791981 | I24: =IF(ABS(H24)<=0.01,"Match",IF(ABS(H24)<=0.05,"Review","Escalate")) -> Review
A25: 24 | B25: France | C25: Dentsu | D25: Feb-2024 | E25: 26874.02 | F25: 26874.02 | G25: =F25-E25 -> 0 | H25: =IFERROR((F25-E25)/E25,0) -> 0 | I25: =IF(ABS(H25)<=0.01,"Match",IF(ABS(H25)<=0.05,"Review","Escalate")) -> Match
... A34: 33 | B34: Germany | C34: Mindshare | D34: Mar-2024 | E34: 17399.96 | F34: 17399.96 | G34: =F34-E34 -> 0 | H34: =IFERROR((F34-E34)/E34,0) -> 0 | I34: =IF(ABS(H34)<=0.01,"Match",IF(ABS(H34)<=0.05,"Review","Escalate")) -> Match
A35: 34 | B35: France | C35: Hearts & Science | D35: Jan-2024 | E35: 67470.07 | F35: Missing | G35: N/A | H35: N/A | I35: Missing Invoice
A36: 35 | B36: France | C36: Publicis | D36: Feb-2024 | E36: 18274.3 | F36: 18274.3 | G36: =F36-E36 -> 0 | H36: =IFERROR((F36-E36)/E36,0) -> 0 | I36: =IF(ABS(H36)<=0.01,"Match",IF(ABS(H36)<=0.05,"Review","Escalate")) -> Match
A37: 36 | B37: Sweden | C37: Dentsu | D37: Jun-2024 | E37: 44431.23 | F37: 43529.45 | G37: =F37-E37 -> -901.78 | H37: =IFERROR((F37-E37)/E37,0) -> -0.020296085 | I37: =IF(ABS(H37)<=0.01,"Match",IF(ABS(H37)<=0.05,"Review","Escalate")) -> Review
A38: 37 | B38: UK | C38: IPG Mediabrands | D38: Mar-2024 | E38: 31663.68 | F38: 31663.68 | G38: =F38-E38 -> 0 | H38: =IFERROR((F38-E38)/E38,0) -> 0 | I38: =IF(ABS(H38)<=0.01,"Match",IF(ABS(H38)<=0.05,"Review","Escalate")) -> Match
A39: 38 | B39: Netherlands | C39: IPG Mediabrands | D39: Jun-2024 | E39: 5256.34 | F39: 5256.34 | G39: =F39-E39 -> 0 | H39: =IFERROR((F39-E39)/E39,0) -> 0 | I39: =IF(ABS(H39)<=0.01,"Match",IF(ABS(H39)<=0.05,"Review","Escalate")) -> Match
A40: 39 | B40: Sweden | C40: Mindshare | D40: Jan-2024 | E40: 54425.47 | F40: 54425.47 | G40: =F40-E40 -> 0 | H40: =IFERROR((F40-E40)/E40,0) -> 0 | I40: =IF(ABS(H40)<=0.01,"Match",IF(ABS(H40)<=0.05,"Review","Escalate")) -> Match
A41: 40 | B41: Germany | C41: WPP Media | D41: Feb-2024 | E41: 81453.5 | F41: 84585.09 | G41: =F41-E41 -> 3131.59 | H41: =IFERROR((F41-E41)/E41,0) -> 0.038446353 | I41: =IF(ABS(H41)<=0.01,"Match",IF(ABS(H41)<=0.05,"Review","Escalate")) -> Review
A42: 41 | B42: France | C42: IPG Mediabrands | D42: Mar-2024 | E42: 25626.48 | F42: 27286.23 | G42: =F42-E42 -> 1659.75 | H42: =IFERROR((F42-E42)/E42,0) -> 0.064766991 | I42: =IF(ABS(H42)<=0.01,"Match",IF(ABS(H42)<=0.05,"Review","Escalate")) -> Escalate
A43: 42 | B43: France | C43: IPG Mediabrands | D43: May-2024 | E43: 8129.86 | F43: 8129.86 | G43: =F43-E43 -> 0 | H43: =IFERROR((F43-E43)/E43,0) -> 0 | I43: =IF(ABS(H43)<=0.01,"Match",IF(ABS(H43)<=0.05,"Review","Escalate")) -> Match
A44: 43 | B44: Germany | C44: Dentsu | D44: Jan-2024 | E44: 69577.29 | F44: 69577.29 | G44: =F44-E44 -> 0 | H44: =IFERROR((F44-E44)/E44,0) -> 0 | I44: =IF(ABS(H44)<=0.01,"Match",IF(ABS(H44)<=0.05,"Review","Escalate")) -> Match
A45: 44 | B45: Sweden | C45: Mindshare | D45: Feb-2024 | E45: 83144.58 | F45: 85903.36 | G45: =F45-E45 -> 2758.78 | H45: =IFERROR((F45-E45)/E45,0) -> 0.033180515 | I45: =IF(ABS(H45)<=0.01,"Match",IF(ABS(H45)<=0.05,"Review","Escalate")) -> Review
A46: 45 | B46: Sweden | C46: Omnicom Media Group | D46: May-2024 | E46: 17466.29 | F46: 17466.29 | G46: =F46-E46 -> 0 | H46: =IFERROR((F46-E46)/E46,0) -> 0 | I46: =IF(ABS(H46)<=0.01,"Match",IF(ABS(H46)<=0.05,"Review","Escalate")) -> Match
A47: 46 | B47: France | C47: IPG Mediabrands | D47: Jan-2024 | E47: 71307.63 | F47: 71307.63 | G47: =F47-E47 -> 0 | H47: =IFERROR((F47-E47)/E47,0) -> 0 | I47: =IF(ABS(H47)<=0.01,"Match",IF(ABS(H47)<=0.05,"Review","Escalate")) -> Match
... A56: 55 | B56: Sweden | C56: Havas Media | D56: May-2024 | E56: 107513.98 | F56: 104326.1 | G56: =F56-E56 -> -3187.88 | H56: =IFERROR((F56-E56)/E56,0) -> -0.029650842 | I56: =IF(ABS(H56)<=0.01,"Match",IF(ABS(H56)<=0.05,"Review","Escalate")) -> Review
...

Sheet 4_Summary_Dashboard
A1: EMEA Commercial Revenue Reconciliation
A3: Revenue by Market (GBP)
A4: Market | B4: Reported Revenue | C4: Invoice Amount | D4: Variance | E4: Variance % | F4: Recon Status Split
A5: France | B5: =SUMIF('3_Reconciliation'!B:B,A5,'3_Reconciliation'!E:E) -> 671163.64 | C5: =SUMIF('3_Reconciliation'!B:B,A5,'3_Reconciliation'!F:F) -> 563695.67 | D5: =C5-B5 -> -107467.97 | E5: =IFERROR(D5/B5,0) -> -0.16012186 | F5: ✓7 ⚠2 ✗5
A6: Germany | B6: =SUMIF('3_Reconciliation'!B:B,A6,'3_Reconciliation'!E:E) -> 1441473.6 | C6: =SUMIF('3_Reconciliation'!B:B,A6,'3_Reconciliation'!F:F) -> 1448012 | D6: =C6-B6 -> 6538.34 | E6: =IFERROR(D6/B6,0) -> 0.0045358721 | F6: ✓11 ⚠4 ✗5
A7: Italy | B7: =SUMIF('3_Reconciliation'!B:B,A7,'3_Reconciliation'!E:E) -> 650462.99 | C7: =SUMIF('3_Reconciliation'!B:B,A7,'3_Reconciliation'!F:F) -> 653958.93 | D7: =C7-B7 -> 3495.94 | E7: =IFERROR(D7/B7,0) -> 0.005374541 | F7: ✓7 ⚠3 ✗1
A8: Netherlands | B8: =SUMIF('3_Reconciliation'!B:B,A8,'3_Reconciliation'!E:E) -> 669344.34 | C8: =SUMIF('3_Reconciliation'!B:B,A8,'3_Reconciliation'!F:F) -> 671636.53 | D8: =C8-B8 -> 2292.19 | E8: =IFERROR(D8/B8,0) -> 0.0034245303 | F8: ✓5 ⚠7 ✗3
A9: Spain | B9: =SUMIF('3_Reconciliation'!B:B,A9,'3_Reconciliation'!E:E) -> 466827.65 | C9: =SUMIF('3_Reconciliation'!B:B,A9,'3_Reconciliation'!F:F) -> 463787.88 | D9: =C9-B9 -> -3039.77 | E9: =IFERROR(D9/B9,0) -> -0.0065115466 | F9: ✓4 ⚠3 ✗1
A10: Sweden | B10: =SUMIF('3_Reconciliation'!B:B,A10,'3_Reconciliation'!E:E) -> 970210.11 | C10: =SUMIF('3_Reconciliation'!B:B,A10,'3_Reconciliation'!F:F) -> 957051.02 | D10: =C10-B10 -> -13159.09 | E10: =IFERROR(D10/B10,0) -> -0.013563134 | F10: ✓8 ⚠9 ✗1
A11: UK | B11: =SUMIF('3_Reconciliation'!B:B,A11,'3_Reconciliation'!E:E) -> 589540.47 | C11: =SUMIF('3_Reconciliation'!B:B,A11,'3_Reconciliation'!F:F) -> 597131.22 | D11: =C11-B11 -> 7590.75 | E11: =IFERROR(D11/B11,0) -> 0.012875706 | F11: ✓5 ⚠3 ✗1
A12: UNKNOWN | B12: =SUMIF('3_Reconciliation'!B:B,A12,'3_Reconciliation'!E:E) -> 49385.72 | C12: =SUMIF('3_Reconciliation'!B:B,A12,'3_Reconciliation'!F:F) -> 48677.34 | D12: =C12-B12 -> -708.38 | E12: =IFERROR(D12/B12,0) -> -0.014343822 | F12: ✓1 ⚠1 ✗0
A13: TOTAL | B13: =SUM(B5:B12) -> 5508408.5 | C13: =SUM(C5:C12) -> 5403950.5 | D13: =SUM(D5:D12) -> -104457.99
A15: Reconciliation Status Summary
A16: Status | B16: Count | C16: % of Total
A17: Match | B17: =COUNTIF('3_Reconciliation'!I:I,"Match") -> 48 | C17: =IFERROR(B17/SUM(B17:B19),0) -> 0.49484536
A18: Review | B18: =COUNTIF('3_Reconciliation'!I:I,"Review") -> 32 | C18: =IFERROR(B18/SUM($B$17:$B$19),0) -> 0.32989691
A19: Escalate | B19: =COUNTIF('3_Reconciliation'!I:I,"Escalate") -> 17 | C19: =IFERROR(B19/SUM($B$17:$B$19),0) -> 0.17525773
A21: Revenue by Agency (GBP)
A22: Agency | B22: Reported Revenue | C22: Invoice Amount | D22: Variance | E22: Variance %
A23: WPP Media | B23: =SUMIF('3_Reconciliation'!C:C,"WPP Media",'3_Reconciliation'!E:E) -> 503495.75 | C23: =SUMIF('3_Reconciliation'!C:C,"WPP Media",'3_Reconciliation'!F:F) -> 507357.69 | D23: =B23-C23 -> -3861.94 | E23: =D23/B23 -> -0.0076702534
A24: IPG Mediabrands | B24: =SUMIF('3_Reconciliation'!C:C,"IPG Mediabrands",'3_Reconciliation'!E:E) -> 359222.05 | C24: =SUMIF('3_Reconciliation'!C:C,"IPG Mediabrands",'3_Reconciliation'!F:F) -> 364679.84 | D24: =B24-C24 -> -5457.79 | E24: =D24/B24 -> -0.01519336
A25: Mindshare | B25: =SUMIF('3_Reconciliation'!C:C,"Mindshare",'3_Reconciliation'!E:E) -> 547693 | C25: =SUMIF('3_Reconciliation'!C:C,"Mindshare",'3_Reconciliation'!F:F) -> 537526.52 | D25: =B25-C25 -> 10166.48 | E25: =D25/B25 -> 0.01856237
A26: MediaCom | B26: =SUMIF('3_Reconciliation'!C:C,"MediaCom",'3_Reconciliation'!E:E) -> 654837.59 | C26: =SUMIF('3_Reconciliation'!C:C,"MediaCom",'3_Reconciliation'!F:F) -> 651685.38 | D26: =B26-C26 -> 3152.21 | E26: =D26/B26 -> 0.0048137279
A27: Havas Media | B27: =SUMIF('3_Reconciliation'!C:C,"Havas Media",'3_Reconciliation'!E:E) -> 816319.44 | C27: =SUMIF('3_Reconciliation'!C:C,"Havas Media",'3_Reconciliation'!F:F) -> 815913.83 | D27: =B27-C27 -> 405.61 | E27: =D27/B27 -> 0.00049687657
A28: Dentsu | B28: =SUMIF('3_Reconciliation'!C:C,"Dentsu",'3_Reconciliation'!E:E) -> 632836.2 | C28: =SUMIF('3_Reconciliation'!C:C,"Dentsu",'3_Reconciliation'!F:F) -> 633079.52 | D28: =B28-C28 -> -243.32 | E28: =D28/B28 -> -0.00038449128
A29: GroupM | B29: =SUMIF('3_Reconciliation'!C:C,"GroupM",'3_Reconciliation'!E:E) -> 226146.32 | C29: =SUMIF('3_Reconciliation'!C:C,"GroupM",'3_Reconciliation'!F:F) -> 224941.29 | D29: =B29-C29 -> 1205.03 | E29: =D29/B29 -> 0.0053285413
A30: Publicis | B30: =SUMIF('3_Reconciliation'!C:C,"Publicis",'3_Reconciliation'!E:E) -> 355438.24 | C30: =SUMIF('3_Reconciliation'!C:C,"Publicis",'3_Reconciliation'!F:F) -> 346881.36 | D30: =B30-C30 -> 8556.88 | E30: =D30/B30 -> 0.024074168
A31: Hearts & Science | B31: =SUMIF('3_Reconciliation'!C:C,"Hearts & Science",'3_Reconciliation'!E:E) -> 897340.78 | C31: =SUMIF('3_Reconciliation'!C:C,"Hearts & Science",'3_Reconciliation'!F:F) -> 796140.76 | D31: =B31-C31 -> 101200.02 | E31: =D31/B31 -> 0.11277769
A32: Omnicom Media Group | B32: =SUMIF('3_Reconciliation'!C:C,"Omnicom Media Group",'3_Reconciliation'!E:E) -> 515079.17 | C32: =SUMIF('3_Reconciliation'!C:C,"Omnicom Media Group",'3_Reconciliation'!F:F) -> 525744.36 | D32: =B32-C32 -> -10665.19 | E32: =D32/B32 -> -0.020705924
A34: Month | B34: Reported Revenue | C34: Invoice Amount | D34: Variance | E34: Variance %
A35: Jan-2024 | B35: =SUMIF('3_Reconciliation'!D:D,"Jan-2024",'3_Reconciliation'!E:E) -> 1446904.9 | C35: =SUMIF('3_Reconciliation'!D:D,"Jan-2024",'3_Reconciliation'!F:F) -> 1387014.5 | D35: =B35-C35 -> 59890.41 | E35: =D35/B35 -> 0.041392084
A36: Feb-2024 | B36: =SUMIF('3_Reconciliation'!D:D,"Feb-2024",'3_Reconciliation'!E:E) -> 677838.88 | C36: =SUMIF('3_Reconciliation'!D:D,"Feb-2024",'3_Reconciliation'!F:F) -> 672096.98 | D36: =B36-C36 -> 5741.9 | E36: =D36/B36 -> 0.0084708921
A37: Mar-2024 | B37: =SUMIF('3_Reconciliation'!D:D,"Mar-2024",'3_Reconciliation'!E:E) -> 1057841.2 | C37: =SUMIF('3_Reconciliation'!D:D,"Mar-2024",'3_Reconciliation'!F:F) -> 1060637.8 | D37: =B37-C37 -> -2796.54 | E37: =D37/B37 -> -0.0026436293
A38: Apr-2024 | B38: =SUMIF('3_Reconciliation'!D:D,"Apr-2024",'3_Reconciliation'!E:E) -> 597399.49 | C38: =SUMIF('3_Reconciliation'!D:D,"Apr-2024",'3_Reconciliation'!F:F) -> 594400.36 | D38: =B38-C38 -> 2999.13 | E38: =D38/B38 -> 0.0050203089
A39: May-2024 | B39: =SUMIF('3_Reconciliation'!D:D,"May-2024",'3_Reconciliation'!E:E) -> 1061369.2 | C39: =SUMIF('3_Reconciliation'!D:D,"May-2024",'3_Reconciliation'!F:F) -> 1049963 | D39: =B39-C39 -> 11406.29 | E39: =D39/B39 -> 0.010746769
A40: Jun-2024 | B40: =SUMIF('3_Reconciliation'!D:D,"Jun-2024",'3_Reconciliation'!E:E) -> 667054.77 | C40: =SUMIF('3_Reconciliation'!D:D,"Jun-2024",'3_Reconciliation'!F:F) -> 639837.97 | D40: =B40-C40 -> 27216.8 | E40: =D40/B40 -> 0.040801447

Sheet 5_Escalation_Log
A1: Row_ID | B1: Market | C1: Partner_Agency | D1: Month | E1: Reported_Revenue_GBP | F1: Invoice_Amount_GBP | G1: Variance_GBP | H1: Variance_Pct | I1: Recon_Status
A2: 7 | B2: Germany | C2: WPP Media | D2: Apr-2024 | E2: 36966.96 | F2: 34953.67 | G2: -2013.29 | H2: -0.054461876 | I2: Escalate
A3: 8 | B3: Sweden | C3: WPP Media | D3: May-2024 | E3: 67099.35 | F3: 62881.26 | G3: -4218.09 | H3: -0.062863351 | I3: Escalate
A4: 26 | B4: France | C4: IPG Mediabrands | D4: May-2024 | E4: 51906.35 | F4: 55704.39 | G4: 3798.04 | H4: 0.073171009 | I4: Escalate
A5: 27 | B5: Germany | C5: Hearts & Science | D5: Jun-2024 | E5: 53645.86 | F5: 57920.34 | G5: 4274.48 | H5: 0.079679588 | I5: Escalate
A6: 31 | B6: Netherlands | C6: Havas Media | D6: May-2024 | E6: 30089.72 | F6: 28344.3 | G6: -1745.42 | H6: -0.058007187 | I6: Escalate
A7: 41 | B7: France | C7: IPG Mediabrands | D7: Mar-2024 | E7: 25626.48 | F7: 27286.23 | G7: 1659.75 | H7: 0.064766991 | I7: Escalate
A8: 47 | B8: Germany | C8: Havas Media | D8: Feb-2024 | E8: 13046.99 | F8: 12304.8 | G8: -742.19 | H8: -0.056885918 | I8: Escalate
A9: 49 | B9: France | C9: MediaCom | D9: Mar-2024 | E9: 34063.95 | F9: 31339.8 | G9: -2724.15 | H9: -0.079971642 | I9: Escalate
A10: 53 | B10: Italy | C10: Hearts & Science | D10: May-2024 | E10: 28430.06 | F10: 26166.69 | G10: -2263.37 | H10: -0.079611862 | I10: Escalate
A11: 62 | B11: France | C11: Hearts & Science | D11: Jan-2024 | E11: 19677.2 | F11: 18140.17 | G11: -1537.03 | H11: -0.078112231 | I11: Escalate
A12: 65 | B12: UK | C12: Havas Media | D12: Mar-2024 | E12: 79766.57 | F12: 84203.41 | G12: 4436.84 | H12: 0.0556228 | I12: Escalate
A13: 69 | B13: France | C13: Omnicom Media Group | D13: Jan-2024 | E13: 71973.22 | F13: 76704.44 | G13: 4731.22 | H13: 0.065735839 | I13: Escalate
... A18: 97 | B18: Germany | C18: Publicis | D18: May-2024 | E18: 58777.98 | F18: 54459.25 | G18: -4318.73 | H18: -0.073475305 | I18: Escalate

Sheet FX_Rates
A1: Month | B1: EUR_to_GBP | C1: GBP_to_GBP
A2: Jan-2024 | B2: 0.8571 | C2: 1
A3: Feb-2024 | B3: 0.8537 | C3: 1
A4: Mar-2024 | B4: 0.8565 | C4: 1
A5: Apr-2024 | B5: 0.8601 | C5: 1
A6: May-2024 | B6: 0.8533 | C6: 1
A7: Jun-2024 | B7: 0.844 | C7: 1

Sheet LookupSheet
A1: sweden | B1: Sweden | C1: Feb-24 | D1: Feb-2024 | E1: confirmed | F1: Confirmed
A2: se | B2: Sweden | C2: 01/2024 | D2: Jan-2024 | E2: pending | F2: Pending
A3: uk | B3: UK | C3: 02/2024 | D3: Feb-2024 | E3: under review | F3: Under Review
A4: u.k. | B4: UK | C4: 03/2024 | D4: Mar-2024 | E4: disputed | F4: Disputed
A5: united kingdom | B5: UK | C5: 04/2024 | D5: Apr-2024 | E5: paid | F5: Paid
A6: germany | B6: Germany | C6: 05/2024 | D6: May-2024
A7: de | B7: Germany | C7: 06/2024 | D7: Jun-2024
A8: deutschland | B8: Germany | C8: Apr-24 | D8: Apr-2024
A9: france | B9: France | C9: April 2024 | D9: Apr-2024
A10: spain | B10: Spain | C10: February 2024 | D10: Feb-2024
A11: es | B11: Spain | C11: Jan-24 | D11: Jan-2024
A12: italy | B12: Italy | C12: January 2024 | D12: Jan-2024
A13: it | B13: Italy | C13: Jun-24 | D13: Jun-2024
A14: italia | B14: Italy | C14: June 2024 | D14: Jun-2024
A15: netherlands | B15: Netherlands | C15: Mar-24 | D15: Mar-2024
A16: nl | B16: Netherlands | C16: March 2024 | D16: Mar-2024
A17: the netherlands | B17: Netherlands | C17: May 2024 | D17: May-2024
A18: France | B18: France | C18: May-24 | D18: May-2024
